Workbook
Name __________________can435: 43.3
Name _________________can435: 43.3
Name ________________can435: 43.3
Name _______________can430: 40.73
Name _______________can435: 43.3
Name ______________can430: 40.73
Name ______________can435: 43.3
Name ______________wrn1: {#N/A,#N/A,FALSE,"Kalk"}
Name ______________wrn2: {"Kalk_druck",#N/A,FALSE,"Kalk";#N/A,#N/A,FALSE,"Risiken";"AllgKost_Druck",#N/A,FALSE,"AllgKost";"KompKost_Druck",#N/A,FALSE,"KompKost"}
Name ______________wrn3: {#N/A,#N/A,FALSE,"Kalk"}
Name _____________can430: 40.73
Name _____________can435: 43.3
Name _____________wrn1: {#N/A,#N/A,FALSE,"Kalk"}
Name _____________wrn2: {"Kalk_druck",#N/A,FALSE,"Kalk";#N/A,#N/A,FALSE,"Risiken";"AllgKost_Druck",#N/A,FALSE,"AllgKost";"KompKost_Druck",#N/A,FALSE,"KompKost"}
Name _____________wrn3: {#N/A,#N/A,FALSE,"Kalk"}
Name ____________can430: 40.73
Name ____________can435: 43.3
Name ____________wrn1: {#N/A,#N/A,FALSE,"Kalk"}
Name ____________wrn2: {"Kalk_druck",#N/A,FALSE,"Kalk";#N/A,#N/A,FALSE,"Risiken";"AllgKost_Druck",#N/A,FALSE,"AllgKost";"KompKost_Druck",#N/A,FALSE,"KompKost"}
Name ____________wrn3: {#N/A,#N/A,FALSE,"Kalk"}
Name ___________can430: 40.73
Name ___________can435: 43.3
Name ___________wrn1: {#N/A,#N/A,FALSE,"Kalk"}
Name ___________wrn2: {"Kalk_druck",#N/A,FALSE,"Kalk";#N/A,#N/A,FALSE,"Risiken";"AllgKost_Druck",#N/A,FALSE,"AllgKost";"KompKost_Druck",#N/A,FALSE,"KompKost"}
Name ___________wrn3: {#N/A,#N/A,FALSE,"Kalk"}
Name __________can430: 40.73
Name __________can435: 43.3
Name __________wrn1: {#N/A,#N/A,FALSE,"Kalk"}
Name __________wrn2: {"Kalk_druck",#N/A,FALSE,"Kalk";#N/A,#N/A,FALSE,"Risiken";"AllgKost_Druck",#N/A,FALSE,"AllgKost";"KompKost_Druck",#N/A,FALSE,"KompKost"}
Name __________wrn3: {#N/A,#N/A,FALSE,"Kalk"}
Name _________can430: 40.73
Name _________can435: 43.3
Name _________wrn1: {#N/A,#N/A,FALSE,"Kalk"}
Name _________wrn2: {"Kalk_druck",#N/A,FALSE,"Kalk";#N/A,#N/A,FALSE,"Risiken";"AllgKost_Druck",#N/A,FALSE,"AllgKost";"KompKost_Druck",#N/A,FALSE,"KompKost"}
Name _________wrn3: {#N/A,#N/A,FALSE,"Kalk"}
Name ________can430: 40.73
Name ________can435: 43.3
Name ________wrn1: {#N/A,#N/A,FALSE,"Kalk"}
Name ________wrn2: {"Kalk_druck",#N/A,FALSE,"Kalk";#N/A,#N/A,FALSE,"Risiken";"AllgKost_Druck",#N/A,FALSE,"AllgKost";"KompKost_Druck",#N/A,FALSE,"KompKost"}
Name ________wrn3: {#N/A,#N/A,FALSE,"Kalk"}
Name _______can430: 40.73
Name _______can435: 43.3
Name _______wrn1: {#N/A,#N/A,FALSE,"Kalk"}
Name _______wrn2: {"Kalk_druck",#N/A,FALSE,"Kalk";#N/A,#N/A,FALSE,"Risiken";"AllgKost_Druck",#N/A,FALSE,"AllgKost";"KompKost_Druck",#N/A,FALSE,"KompKost"}
Name _______wrn3: {#N/A,#N/A,FALSE,"Kalk"}
Name _______ys1: {#N/A,#N/A,FALSE,"abs";#N/A,#N/A,FALSE,"Annex-I";#N/A,#N/A,FALSE,"Annex-II";#N/A,#N/A,FALSE,"Annex-III";#N/A,#N/A,FALSE,"Annex-IV";#N/A,#N/A,FALSE,"Annex-V";#N/A,#N/A,FALSE,"Annex-VI"}
Name ______can430: 40.73
Name ______can435: 43.3
Name ______wrn1: {#N/A,#N/A,FALSE,"Kalk"}
Name ______wrn2: {"Kalk_druck",#N/A,FALSE,"Kalk";#N/A,#N/A,FALSE,"Risiken";"AllgKost_Druck",#N/A,FALSE,"AllgKost";"KompKost_Druck",#N/A,FALSE,"KompKost"}
Name ______wrn3: {#N/A,#N/A,FALSE,"Kalk"}
Name ______xlnm.Print_Area_2: "'Stur-Detailed'!$A$1:$E$108"
Name ______xlnm.Print_Area_3: "'Service - Low'!$A$1:$E$47"
Name ______xlnm.Print_Area_4: "'Masonary & Plastring'!$A$1:$E$73"
Name ______xlnm.Print_Area_6: "'Interiors & Softfurnishing'!$A$1:$E$19"
Name ______xlnm.Print_Titles_2: "'Stur-Detailed'!$6:$6"
Name ______xlnm.Print_Titles_4: "'Masonary & Plastring'!$6:$6"
Name ______xlnm.Print_Titles_6: "'Interiors & Softfurnishing'!$6:$6"
Name ______xlnm.Print_Titles_7: "'Windows & Clading Works'!$6:$6"
Name ______ys1: {#N/A,#N/A,FALSE,"abs";#N/A,#N/A,FALSE,"Annex-I";#N/A,#N/A,FALSE,"Annex-II";#N/A,#N/A,FALSE,"Annex-III";#N/A,#N/A,FALSE,"Annex-IV";#N/A,#N/A,FALSE,"Annex-V";#N/A,#N/A,FALSE,"Annex-VI"}

Sheet Bill Tracker
A1: Project | B1: : Sattva City | D1: Date: | E1: 21.07.2025
A2: Vendor | B2: : Pragathi Landscapers LLP
A3: WO NO | B3: : 4300006116
A4: WO Value | B4: : Rs. 1,44,70,656.36/-
A5: Nature of Work | B5: : Landscape Works
A6: RA Bill No | B6: : 05
A7: Bill Period | B7: : 07.05.2025 to 04.07.2025
A9: WORK BILL TRACKING CHART
A10: S No | B10: Particulars | C10: Date | D10: No of Days Taken | E10: Reasons for Delay if any
A12: A | B12: PROJECTS/SITE QS/CONTRACTS DEPT.
A13: 1 | B13: Document date | C13: 05.07.2025
A14: 2 | B14: Bill Received by Project In-charge | C14: 16.07.2025
A15: 3 | B15: Bill Received by Site QS | C15: 16.07.2025
A16: 4 | B16: Contractor QS/Reqd. Information/Attachment not available
A17: 5 | B17: Other delays if any
A18: 6 | B18: Amendment/Open WO request sent to Planning
A19: 7 | B19: PR Raised by planning
A20: 8 | B20: Amendment released by Contract/Purchase Dept
A21: 9 | B21: Bill approved by Site In-charge
A22: 10 | B22: Certified/SES Entry made by Site QS (1st Level) | C22: =E1 -> 21.07.2025
A24: B | B24: BILLING, HO
A25: 1 | B25: Bill Received at HO QS
A26: 2 | B26: Bill Processed to Billing A/C
A27: 3 | B27: SES 2nd level Release
A28: 4 | B28: Tax Invoice Date
A29: 5 | B29: Corrected Tax Invoice Received
A30: 6 | B30: Parking Date
A31: 7 | B31: Received duly approved
A32: 8 | B32: Posting Date
A33: 9 | B33: Handedover to Acct. Dept.
A35: C | B35: ACCOUNTS
A36: 1 | B36: Cheque Signing List
A37: 2 | B37: Cheque handedover to Vendor.
A39: SAP WO | B39: =B3 -> : 4300006116
A40: SES NO | B40: :
A41: SAP Amount | B41: :
A42: Bill Period | B42: =B7 -> : 07.05.2025 to 04.07.2025

Sheet PRAG SUMMURY 
A2: PROJECT :SATTVA CITY
A3: CLIENT : SATTVA CITY PRIVATE LIMITED
A4: CONTRACTOR : M/S PRAGATHI LANDSCAPERS LLP
A5: WO NO: 4300006116/R1 DATED : 03-10-2024
A6: NATURE OF WORK: HARDSCAPE WORKS | D6: RA BILL-04
F7: DATE: 14-07-2025
A8: SL No. | B8: DESCRIPTION | C8: BOQ AMOUNT | D8: PREVIOUS | E8: CURRENT | F8: CUMMULATIVE | G8: REMARKS
A10: 1 | B10: HARDSCAPE WORKS | C10: 19856639 | D10: ='Abstract '!K50 | E10: =F10-D10 -> 632733.44 | F10: ='Abstract '!M50 -> 632733.44
B12: SUB - TOTAL | C12: =SUM(C10) -> 19856639 | D12: =SUM(D10) -> 0 | E12: =SUM(E10) -> 632733.44 | F12: =SUM(F10) -> 632733.44
B13: GST @ 18% | C13: =C12*18% -> 3574195 | D13: =D12*18% -> 0 | E13: =E12*18% -> 113892.02 | F13: =F12*18% -> 113892.02
B14: GRAND TOTAL | C14: =C12+C13 -> 23430834 | D14: =D12+D13 -> 0 | E14: =E12+E13 -> 746625.46 | F14: =F12+F13 -> 746625.46

Sheet PRAG SUM
B2: PROJECT :SATTVA CITY
B3: CLIENT : SATTVA CITY PRIVATE LIMITED
B4: CONTRACTOR : M/S PRAGATHI LANDSCAPERS LLP
B5: WO NO: 4300006116/R1 DATED : 03-10-2024
B6: NATURE OF WORK: HARDSCAPE WORKS | E6: RA BILL-03
G7: DATE: 06-05-2025
B8: SL No. | C8: DESCRIPTION | D8: BOQ AMOUNT | E8: PREVIOUS | F8: CURRENT | G8: CUMMULATIVE | H8: REMARKS
B10: 1 | C10: HARDSCAPE WORKS | D10: ='Abstract '!G50 -> 589247.24 | E10: ='Abstract '!K50 | F10: ='Abstract '!L50 -> 632733.44 | G10: ='Abstract '!M50 -> 632733.44
C12: SUB - TOTAL | D12: =SUM(D10) -> 589247.24 | E12: =SUM(E10) -> 0 | F12: =SUM(F10) -> 632733.44 | G12: =SUM(G10) -> 632733.44
C13: GST @ 18% | D13: =D12*18% -> 106064.5 | E13: =E12*18% -> 0 | F13: =F12*18% -> 113892.02 | G13: =G12*18% -> 113892.02
C14: GRAND TOTAL | D14: =D12+D13 -> 695311.74 | E14: =E12+E13 -> 0 | F14: =F12+F13 -> 746625.46 | G14: =G12+G13 -> 746625.46

Sheet PRAG SUMMURY
B2: PROJECT :SATTVA CITY
B3: CLIENT : SATTVA CITY PRIVATE LIMITED
B4: CONTRACTOR : M/S PRAGATHI LANDSCAPERS LLP
B5: WO NO: 4300006116/R1 DATED : 03-10-2024
B6: NATURE OF WORK: HARDSCAPE WORKS | E6: RA BILL-05 & FINAL
G7: DATE: 23-10-2025
B8: SL No. | C8: DESCRIPTION | D8: BOQ AMOUNT | E8: PREVIOUS | F8: CURRENT | G8: CUMMULATIVE | H8: REMARKS
B10: 1 | C10: HARDSCAPE WORKS | D10: ='[1]Abstract '!G39 -> #REF! | E10: ='Abstract '!K39 -> 8162761.1 | F10: =G10-E10 -> #REF! | G10: ='Abstract '!M39 -> #REF!
B12: 2 | C12: NT ITEMS | D12: 589247.24 | E12: ='Abstract '!K50 | F12: =G12-E12 -> 632733.44 | G12: ='Abstract '!M50 -> 632733.44
C14: SUB - TOTAL | D14: =SUM(D10) -> #REF! | E14: =SUM(E10:E12) -> 8162761.1 | F14: =SUM(F10:F12) -> #REF! | G14: =SUM(G10:G12) -> #REF!
C15: GST @ 18% | D15: =D14*18% -> #REF! | E15: =E14*18% -> 1469297 | F15: =F14*18% -> #REF! | G15: =G14*18% -> #REF!
C16: GRAND TOTAL | D16: =D14+D15 -> #REF! | E16: =E14+E15 -> 9632058.1 | F16: =F14+F15 -> #REF! | G16: =G14+G15 -> #REF!

Sheet Abstract 
A1: Project | B1: ='Bill Tracker'!B1 -> : Sattva City
A2: Vendor | B2: ='Bill Tracker'!B2 -> : Pragathi Landscapers LLP
A3: WO NO | B3: ='Bill Tracker'!B3 -> : 4300006116
A4: WO Value | B4: ='Bill Tracker'!B4 -> : Rs. 1,44,70,656.36/-
A5: Nature of Work | B5: ='Bill Tracker'!B5 -> : Landscape Works
A6: RA Bill No | B6: ='Bill Tracker'!B6 -> : 05
A7: Bill Period | B7: ='Bill Tracker'!B7 -> : 07.05.2025 to 04.07.2025
A8: ABSTRACT
A9: Sr.No | B9: Description | C9: SAP CODE | D9: Unit | E9: BOQ Qty | F9: Rate | G9: Amount | H9: Quantity | K9: Amount | N9: Remarks
H10: Previous | I10: Present | J10: Cumulative | K10: Previous | L10: Present | M10: Cumulative
A11: 10 | B11: Marketing office front area Hardscape
A12: 10 | B12: LAND_BASE PREPARATION BASE PREPARATION WORKS Clearing and grubbing of top 150mm top soil including cutting, removing and disposing of all materials such as trees, bushes, shrubs, stumps, roots, grass, weeds, top organic soil etc. complete. | C12: 55008371 | D12: M2 | E12: 6230.157 | F12: 60 | G12: =+E12*F12 -> 373809.42 | H12: 269.48732 | I12: =+J12-H12 -> 0 | J12: ='M BOOK'!I410 -> 269.48732 | K12: =+F12*H12 -> 16169.239 | L12: =+F12*I12 -> 0 | M12: =+J12*F12 -> 16169.239 | O12: =E12-J12 -> 5960.6697
A13: 20 | B13: LAND_SUP/FlX_PIain Concrete M10 grade PCC WORKS (1:4:8) Providing and laying Plain cement concrete 1:4:8 mix of following to the depth at locations specified at all levels using river sand, graded granite aggregate of 20mm and down size including base preparation, compaction. levelling, all leads and lifts, curing and shuttering if necessary etc., complete as per drawings. (100mm thick PCC) | C13: 55007038 | D13: M3 | E13: 623.016 | F13: 4950 | G13: =+E13*F13 -> 3083929.2 | H13: 210.01479 | I13: =+J13-H13 -> -1.0125 | J13: ='M BOOK'!I196 -> 209.00229 | K13: =+F13*H13 -> 1039573.2 | L13: =+F13*I13 -> -5011.875 | M13: =+J13*F13 -> 1034561.3 | O13: =E13-J13 -> 414.01371
A14: 30 | B14: 55009582 LAND_SUP/FIX_GRANITE COBBLE HARDSCAPE WORKS Black flamed Granite Cobble Stone Providing & laying of Black Granite Cobble stones of 100X100mm over 50mm thick pcc bed to required shape, size and pattern .to required line, level, etc. all complete cost including of all materials at site, necessary earth compaction, all labour charges and other charges required to complete. Location - Driveway paving band (75mm thick) | C14: 65000300 | D14: M2 | E14: 225 | F14: 3230 | G14: =+E14*F14 -> 726750 | H14: 211.5 | I14: =+J14-H14 -> 0 | J14: ='M BOOK'!I355 -> 211.5 | K14: =+F14*H14 -> 683145 | L14: =+F14*I14 -> 0 | M14: =+J14*F14 -> 683145 | O14: =E14-J14 -> 13.5
A15: 40 | B15: 55009582 LAND_SUP/FIX_GRANITE COBBLE Same as above, for paving band (40mm thick)- Pedestrian walkway | C15: 65000300 | D15: M2 | E15: 0.001 | F15: 3230 | G15: =+E15*F15 -> 3.23 | I15: =+J15-H15 -> 0 | K15: =+F15*H15 -> 0 | L15: =+F15*I15 -> 0 | M15: =+J15*F15 -> 0 | O15: =E15-J15 -> 0.001
A16: 50 | B16: LAND_FIX_CONCRETE KERBS Precast Concrete Kerb Receiving and fixing of Precast Concrete kerbs of size 150mm thick of approved make, on cement concrete base of 1:3:6 mix as per dwg, cost including all materials at site, necessary earth excavation, all labour Charges and other necessary charges all as per drawings. Location- Along Driveway | C16: 53003478 | D16: M | E16: 2318.5 | F16: 475 | G16: =+E16*F16 -> 1101287.5 | H16: 1089.1808 | I16: =+J16-H16 -> 22.66 | J16: ='M BOOK'!I96 -> 1111.8408 | K16: =+F16*H16 -> 517360.88 | L16: =+F16*I16 -> 10763.5 | M16: =+J16*F16 -> 528124.38 | O16: =E16-J16 -> 1206.6592
A17: 60 | B17: LAND_FIX_FLUSH KERBS Flush Kerb Kerbs: Receiving and fixing of Concrete flush type kerbs of size 100x300x600mm of approved make with Matte Finish, on cement concrete base of 1:3:6mix as per dwg, cost including all materials at site, necessary earth excavation. all labour charges and other necessary charges all as per drawings. Location- Along Pedestrian walkway | C17: 53003479 | D17: M | E17: 1364.75 | F17: 450 | G17: =+E17*F17 -> 614137.5 | H17: 1143.7395 | I17: =+J17-H17 -> 22.66 | J17: ='M BOOK'!I130 -> 1166.3995 | K17: =+F17*H17 -> 514682.78 | L17: =+F17*I17 -> 10197 | M17: =+J17*F17 -> 524879.78 | O17: =E17-J17 -> 198.3505 | S17: 1292.24
A18: 70 | B18: Land_sup/fix_pebbles Pebbles Supply and laying of "River washed Pebbles" of 40-50 mm dia or as per drawings. The quoted rate shall include the cost of supply, transport and laying in layers, pattern, etc., complete with cement mortor Location- Laid on waterbody drain | C18: 55003457 | D18: KG | E18: 0.001 | F18: 72 | G18: =+E18*F18 -> 0.072 | I18: =+J18-H18 -> 0 | K18: =+F18*H18 -> 0 | L18: =+F18*I18 -> 0 | M18: =+J18*F18 -> 0 | O18: =E18-J18 -> 0.001
A19: 80 | B19: LAND_FIX_BALCK GRANITE Granite Flooring Receiving and laying in position of approved Polished Jet Black Granite stone flooring of size 20mm thick as per selection laid over a bed of minimum 35mm thick cemen mortar 1:4 to the approved pattern as per the detail drawings. The joints shall be pointed with the matching cement based polymer grout with polished and unpolished surfaces of the granite slabs shall be finished with sealer coats as recommended by Laticrete/ Bal Endura/ Aqua mix or approved equivalent make and complete. Pre-polished granite slabs shall have the edges machine cut to precise sizes to produce very fine joints. All the exposed edges of the flooring shall be machine polished to profiles as per the detail drawings. This also includes providing top covering over the polythene sheets for the entire flooring to protect against scratches etc. Location- Water Feature | C19: 55007750 | D19: M2 | E19: 0.001 | F19: 1065 | G19: =+E19*F19 -> 1.065 | H19: 0 | I19: =+J19-H19 -> 0 | J19: 0 | K19: =+F19*H19 -> 0 | L19: =+F19*I19 -> 0 | M19: =+J19*F19 -> 0 | O19: =E19-J19 -> 0.001
A20: 90 | B20: F/C_FIX_Granite Cladding Granite Cladding Receving and fixing in position of 40-50mm thick approved Polished Jet Black Granite stone cladding to walls, columns and other vertical faces as called for fixed over a backing of avg 25mm thick cement mortar 1:4 and Grey Cement paste CM 1:1 to pattern as per the detail drawings. The joints shall be pointed with the matching cement based polymer grout by Laticrete or approved equivalent make and complete. Rate includes necessary scaffolding, staging, curing, etc., complete as per the instructions of the Architect / Engineer in charge. The slabs shall have the edges machine cut and polished to produce very fine joints. The cladding shall be polished if required to give the final finish as desired by architects. Rate to include wastage, providing necessary V-grooves in the joints, Granite insets in different vertical and horizontal levels/ plane as per the detail drawings if required. Location- Water Feature Location- Planter | C20: 52000566 | D20: M2 | E20: 0.001 | F20: 1136 | G20: =+E20*F20 -> 1.136 | I20: =+J20-H20 -> 0 | K20: =+F20*H20 -> 0 | L20: =+F20*I20 -> 0 | M20: =+J20*F20 -> 0 | O20: =E20-J20 -> 0.001
A21: 100 | B21: F/C_FlX_Granite Cladding above line item Location- Planter | C21: 52000566 | D21: M2 | E21: 0.001 | F21: 1136 | G21: =+E21*F21 -> 1.136 | I21: =+J21-H21 -> 0 | K21: =+F21*H21 -> 0 | L21: =+F21*I21 -> 0 | M21: =+J21*F21 -> 0 | O21: =E21-J21 -> 0.001
A22: 110 | B22: LAND_GRANITE COPING Granite Coping Receiving & Laying of 40mm thick Polished Jet Black Granite, flamed finish coping with full nosing, edge polishing on both sides in CM 1:4 over minimum thickness of 25-30mm over the masonry/RCC. The rate shall include cutting required size. laying, grouting, curing. edge finishing etc complete. Location- Water Feature 300mm width | C22: 55005650 | D22: M | E22: 0.001 | F22: 1080 | G22: =+E22*F22 -> 1.08 | I22: =+J22-H22 -> 0 | K22: =+F22*H22 -> 0 | L22: =+F22*I22 -> 0 | M22: =+J22*F22 -> 0 | O22: =E22-J22 -> 0.001
A23: 120 | B23: LAND_GRANITE COPING above line item Location- Planter 450 mm width | C23: 55005650 | D23: M | E23: 0.001 | F23: 1165 | G23: =+E23*F23 -> 1.165 | I23: =+J23-H23 -> 0 | K23: =+F23*H23 -> 0 | L23: =+F23*I23 -> 0 | M23: =+J23*F23 -> 0 | O23: =E23-J23 -> 0.001
A24: 130 | B24: LAND_FIX_CONCRETE PAVERS Concrete Pavers Receving and fixing of Concrete Pavers blocks of 200 x 100 X 80mm. laid over 35mm thick cemen mortar 1:4 , joints to be cleaned, curing, cleaning, etc. to required line, level, etc. all complete cost including of all materials at site, necessary earth compaction, all labour charges and other charges required to complete. Color- Dark Grey. For Pedestrian walkway -80mm Thick Paver | C24: 53003477 | D24: M2 | E24: 962.628 | F24: 410 | G24: =+E24*F24 -> 394677.48 | H24: 771.56951 | I24: =+J24-H24 -> 1066.5002 | J24: ='M BOOK'!I268 -> 1838.0697 | K24: =+F24*H24 -> 316343.5 | L24: =+F24*I24 -> 437265.08 | M24: =+J24*F24 -> 753608.57 | O24: =E24-J24 -> -875.44169
A25: 140 | B25: Land_SUP/Lay_Brush Finish Concrete Broom Finish Concrete Providing and laying of Concrete in M25 grade screed with water cement ratio of 0.5 of average thickness of 150mm as directed during execution and shall be laid in bays of suitable sizes and to required slope in a alternate panel fashion and neatly finished with power trowelled and lines drawn as directed, Screed Concrete shall be laid in One layer with 10 mm and down size graded stone aggregates This layer shall be thoroughly tamped, spread,incIusive of Power trowelled and finished smooth with E floating coat of neat cement. No dry cement shall be allowed to be used for finishing the surface. The surface shall be kept well watered after it is dry for a period of 8 days. Cost Shall be inclusive of making sub base area clean by removing dead mortor/concrete by chipping and laying the concrete in panels o 4mx4m providing suitable grooves. The surface Shall be finished with troll finish/broom finish etc complete. The construction joint shall be cut using diamond bit wheel for a width of 3 to 4mm and a depth of 30mm within 20 to 30 hours of concreting, no delay shall be acceptable. On curing and drying of the concrete the construction joints have to be filled with sealants as per manufacturers specification. Location- Entry Ramp | C25: 55004902 | D25: M2 | E25: 0.001 | F25: 5800 | G25: =+E25*F25 -> 5.8 | I25: =+J25-H25 -> 0 | K25: =+F25*H25 -> 0 | L25: =+F25*I25 -> 0 | M25: =+J25*F25 -> 0 | O25: =E25-J25 -> 0.001
A26: 150 | B26: LAND_POW ER TROWEL Power Trowel with broom finish for above item | C26: 55009607 | D26: M2 | E26: 1051.058 | F26: 115 | G26: =+E26*F26 -> 120871.67 | H26: 2467.1711 | I26: =+J26-H26 -> 620.76992 | J26: ='M BOOK'!I389 -> 3087.941 | K26: =+F26*H26 -> 283724.67 | L26: =+F26*I26 -> 71388.541 | M26: =+J26*F26 -> 355113.21 | O26: =E26-J26 -> -2036.883
A27: 160 | B27: LAND_GROOVE CUTTING Groove cutting for above item | C27: 55007653 | D27: M | E27: 210.8 | F27: 60 | G27: =+E27*F27 -> 12648 | H27: 357.8 | I27: =+J27-H27 -> 0 | J27: ='M BOOK'!I400 -> 357.8 | K27: =+F27*H27 -> 21468 | L27: =+F27*I27 -> 0 | M27: =+J27*F27 -> 21468 | O27: =E27-J27 -> -147
A28: 20 | B28: NT ITEMS-26-14127 | O28: =E28-J28 -> 0
A29: 10 | B29: Land_Sup/Fix_Granular Sub Base Providing & laying of Granular Sub-base with Coarse Graded material (Table:- 400-2) compacted thickness of 150mm by providing, laying, spreading and compacting , spreading in uniform layers with motor grader on prepared surface, mixing by mix in place method with rotavator at OMC, and compacting with vibratory roller 8-10 tonne to achieve the desired density of 98% including protection of edges of GSB layer, cost of all materials, labour, hire charges of machinery, loading & Unloading, all lead and lift etc., complete. as per the directions of eng-in- charge of work in accordance Technical Specification | C29: 55007561 | D29: M3 | E29: 1654.823 | F29: 2050 | G29: =+E29*F29 -> 3392387.1 | H29: 939.1261 | I29: =+J29-H29 -> 3.9111185 | J29: ='M BOOK'!I69 -> 943.03722 | K29: =+F29*H29 -> 1925208.5 | L29: =+F29*I29 -> 8017.7929 | M29: =+J29*F29 -> 1933226.3 | N29: ='DC S '!G69 -> #REF! | O29: =E29-J29 -> 711.78578
A30: 20 | B30: Land_SUP/FlX_Wet Mix Macadam Providing,laying 2 layers WMM (Wet mix macadem) with Stone aggregate with approved quality of 20mm down grade and quarry dust, well packed, correct to level. The surface shall be consolidated by 8 to 10 Tonne power road roller after spreading of well compacted earth or boulder soling as the sub base etc., complete. The finish consolidated thickness shall be 150mm. | C30: 55007682 | D30: M3 | E30: 945.768 | F30: 2325 | G30: =+E30*F30 -> 2198910.6 | H30: 649.55112 | I30: =+J30-H30 -> 0 | J30: ='M BOOK'!I241 -> 649.55112 | K30: =+F30*H30 -> 1510206.4 | L30: =+F30*I30 -> 0 | M30: =+J30*F30 -> 1510206.4 | N30: ='DC S '!G131 -> #REF! | O30: =E30-J30 -> 296.21688
A31: 30 | B31: Land__SUP/FILL_sweet earth fill Shifting and Filling of existing soil within the site for planter box and any other location manually with consolidation. | C31: 55002290 | D31: M3 | E31: 1197.126 | F31: 240 | G31: =+E31*F31 -> 287310.24 | H31: 1430.4246 | I31: =+J31-H31 -> #REF! | J31: ='M BOOK'!I225 -> #REF! | K31: =+F31*H31 -> 343301.9 | L31: =+F31*I31 -> #REF! | M31: =+J31*F31 -> #REF! | O31: =E31-J31 -> #REF!
A32: 40 | B32: Receiving & fixing reinforcement for RCC work with high yield strength ribbed cold twisted for steel of various diameters of grade Fe-500 confirming to BIS specificationincluding cutting, bending, fabricating, & placing in position according to drawings & binding the reinforcement with the use of 18 guage MS binding wire of double fold & providing precast cement cover blocks for main reinforecements to ensure specified cover according to relevant IS code. The measurements will be in accordance with the code IS: 1200. Note: Unless noted otherwise the measurements in accordance with IS: 1200 or equivalent BS codes. However reinforcement shall be measured only in lengths of bars as actually placed in position on standard weight basis, no allowance being made in the weight for rolling margin. Authorised laps and splices only will be measured. Chairs of any shape and profile, Spacer bar of any bshape & profile, cover block, wastage & binding wire will not be measured & shall be included in the quote rates. Quoted rate shall be deemed to have considered the above stipulation. | C32: 55010117 | D32: KG | E32: 27859.056 | F32: 16 | G32: =+E32*F32 -> 445744.9 | H32: 7260.4753 | I32: =+J32-H32 -> #REF! | J32: =BBS!O69 -> #REF! | K32: =+F32*H32 -> 116167.6 | L32: =+F32*I32 -> #REF! | M32: =+J32*F32 -> #REF! | O32: =E32-J32 -> #REF!
A33: 50 | B33: CHAMBER WORK (900*900* Depth up to 1.5mt) Excavation, Compaction, PCC Providing and laying 6 inch block masonry in cement mortar 1:3 (1 cement : 3 coarse sand) of in true line level and plumb for walls, with necessary scaffolding, curing etc., Providing, applying of External & internal plastering in c.m. 1:3, 15-20mm thick Single Coat including necessary scaffolding, as per design, curing and hacking to the surfaces & finish including chamber cover fixing on the top etc., complete. (Note: chamber cover supply by sattva). | C33: 55008193 | D33: NOS | E33: 11 | F33: 17400 | G33: =+E33*F33 -> 191400 | H33: 11 | I33: =+J33-H33 -> 8 | J33: ='M BOOK'!I316 -> 19 | K33: =+F33*H33 -> 191400 | L33: =+F33*I33 -> 139200 | M33: =+J33*F33 -> 330600 | O33: =E33-J33 -> -8
A34: 60 | B34: CHAMBER WORK (450*450* Depth up to 0.7mt) Excavation, Compaction, PCC Providing and laying 6 inch block masonry in cement mortar 1:3 (1 cement : 3 coarse sand) of in true line level and plumb for walls, with necessary scaffolding, curing etc., Providing, applying of External & internal plastering in c.m. 1:3, 15-20mm thick Single Coat including necessary scaffolding, as per design, curing and hacking to the surfaces & finish including chamber cover fixing on the top etc., complete. (Note: chamber cover supply by sattva) | C34: 55008193 | D34: NOS | E34: 23 | F34: 5200 | G34: =+E34*F34 -> 119600 | H34: 0 | I34: =+J34-H34 -> 0 | J34: 0 | K34: =+F34*H34 -> 0 | L34: =+F34*I34 -> 0 | M34: =+J34*F34 -> 0 | O34: =E34-J34 -> 23
A35: 70 | B35: CHAMBER WORK (600*600* Depth up to 01mt) Excavation, Compaction, PCC Providing and laying 6 inch block masonry in cement mortar 1:3 (1 cement : 3 coarse sand) of in true line level and plumb for walls, with necessary scaffolding, curing etc., Providing, applying of External & internal plastering in c.m. 1:3, 15-20mm thick Single Coat including necessary scaffolding, as per design, curing and hacking to the surfaces & finish and including chamber cover fixing on the top etc., complete. (Note: chamber cover supply by sattva) | C35: 55006453 | D35: NOS | E35: 4 | F35: 8500 | G35: =+E35*F35 -> 34000 | H35: 4 | I35: =+J35-H35 -> 0 | J35: ='M BOOK'!I324 -> 4 | K35: =+F35*H35 -> 34000 | L35: =+F35*I35 -> 0 | M35: =+J35*F35 -> 34000 | O35: =E35-J35 -> 0
A36: 80 | B36: CHAMBER WORK (750*750* Depth up to 01mt) Excavation, Compaction, PCC Providing and laying 6 inch block masonry in cement mortar 1:3 (1 cement : 3 coarse sand) of in true line level and plumb for walls, with necessary scaffolding, curing etc., Providing, applying of External & internal plastering in c.m. 1:3, 15-20mm thick Single Coat including necessary scaffolding, as per design, curing and hacking to the surfaces & finish including chamber cover fixing on the top etc., complete. (Note: chamber cover supply by sattva) | C36: 55008193 | D36: NOS | E36: 4 | F36: 10000 | G36: =+E36*F36 -> 40000 | H36: 4 | I36: =+J36-H36 -> 0 | J36: ='M BOOK'!I333 -> 4 | K36: =+F36*H36 -> 40000 | L36: =+F36*I36 -> 0 | M36: =+J36*F36 -> 40000 | O36: =E36-J36 -> 0
A37: 90 | B37: CHAMBER WORK (300*300* Depth up to 0.1mt) Excavation, Compaction, PCC Providing and laying 6 inch block masonry in cement mortar 1:3 (1 cement : 3 coarse sand) of in true line level and plumb for walls, with necessary scaffolding, curing etc., Providing, applying of External & internal plastering in c.m. 1:3, 15-20mm thick Single Coat including necessary scaffolding, as per design, curing and hacking to the surfaces & finish including chamber cover fixing on the top etc., complete. (Note: chamber cover supply by sattva) | C37: 55008193 | D37: NOS | E37: 28 | F37: 5500 | G37: =+E37*F37 -> 154000 | H37: 12 | I37: =+J37-H37 -> 18 | J37: ='M BOOK'!I346 -> 30 | K37: =+F37*H37 -> 66000 | L37: =+F37*I37 -> 99000 | M37: =+J37*F37 -> 165000 | O37: =E37-J37 -> -2
A38: 100 | B38: Receiving and laying controlled Reinforced Cement Concrete of M30 grade at all levels and heights specified below using ordinary Portland cement of grade 43 from approved manufacturer, river sand, 20mm and down size coarse aggregates, necessary admixtures approved by Consultants (Conplast SP-430SRV from Fosroc or equivalent), including all leads and lifts, pumping using line pump or boom placer, vibrating/compaction, scaffolding wherever necessary, all lead and lifts, tools & Plants, pumping the concrete to all levels, curing etc. complete but excluding cost of reinforcement and formwork, centering, shuttering. Depending on the size and location, the maximum depth of concreting will be decided by Engineer in casting at a time. | C38: 55008466 | D38: M3 | E38: 1071.98 | F38: 1100 | G38: =+E38*F38 -> 1179178 | H38: 494.55402 | I38: =+J38-H38 -> 122.12936 | J38: ='M BOOK'!I308 -> 616.68338 | K38: =+F38*H38 -> 544009.43 | L38: =+F38*I38 -> 134342.29 | M38: =+J38*F38 -> 678351.72 | O38: =E38-J38 -> 455.29662
B39: Total Amount | G39: =SUM(G12:G38) -> 14470656 | K39: =SUM(K1:K38) -> 8162761.1 | L39: =SUM(L1:L38) -> #REF! | M39: =SUM(M1:M38) -> #REF! | O39: =E39-J39 -> 0
A40: 30 | B40: NT ITEMS-25-15179 | O40: =E40-J40 -> 0
...

Sheet NT MEAS
B2: NON-TENDERED ITEMS
B4: MEASUREMENT BACK UP
B5: SL.NO | C5: DESCRIPTION | D5: UNIT | E5: NOS | F5: L | G5: B | H5: D | I5: QTY | J5: REMARKS
B7: NT-01 | C7: SAUCER DRAIN | D7: RMT
C8: RA BILL-02
B9: AREA-01 | C9: MARKETING OFFICE DROP OFF | E9: 1 | F9: =J9/1000 -> 50.0706 | I9: =PRODUCT(E9:H9) -> 50.0706 | J9: 50070.6
E10: 1 | F10: =J10/1000 -> 18.7304 | I10: =PRODUCT(E10:H10) -> 18.7304 | J10: 18730.4
C11: RA BILL-03
B12: AREA-01 | C12: MAIN DRIVEWAY AREA | E12: 1 | F12: =J12/1000 -> 120.011 | I12: =PRODUCT(E12:H12) -> 120.011 | J12: 120011
C13: RA BILL-04
B14: AREA-01 | C14: MAIN DRIVEWAY AREA | E14: 1 | F14: =J14/1000 -> 40.0109 | I14: =PRODUCT(E14:H14) -> 40.0109 | J14: 40010.9
C16: RA BILL-04
B17: AREA-01 | C17: MAIN DRIVEWAY AREA | E17: 1 | F17: =J17/1000 -> 40.0109 | I17: =PRODUCT(E17:H17) -> 40.0109 | J17: 40010.9
B18: AREA-02 | C18: ROUNDABOUT AREA | E18: 1 | F18: =J18/1000 -> 22.815 | I18: =PRODUCT(E18:H18) -> 22.815 | J18: 22815
B19: AREA-03 | C19: ROUNDABOUT AREA | E19: 1 | F19: =J19/1000 -> 15.8189 | I19: =PRODUCT(E19:H19) -> 15.8189 | J19: 15818.9
C20: TOTAL | I20: =SUM(I9:I19) -> 307.4677 | J20: RMT | L20: =312.47/0.6 -> 520.78333
B22: SL.NO | C22: DESCRIPTION | D22: UNIT | E22: NOS | F22: L | G22: B | H22: D | I22: QTY | J22: REMARKS
B24: NT-02 | C24: 40MM THICK STEEL GREY FLAMED FINISH GRANITE FLOORING | D24: SQM
C25: RA BILL-02
B26: AREA-01 | C26: MARKETING OFFICE DROP OFF | E26: 1 | F26: =J26/(1000*1000) -> 99.91514 | I26: =PRODUCT(E26:H26) -> 99.91514 | J26: 99915140
C29: TOTAL | I29: =SUM(I26:I27) -> 99.91514 | J29: SQM
B31: SL.NO | C31: DESCRIPTION | D31: UNIT | E31: NOS | F31: L | G31: B | H31: D | I31: QTY | J31: REMARKS
B33: NT-03 | C33: HDPE SHEET 600 MICRON BELOW M30 CONCRETE | D33: SQM
C34: RA BILL-02
B35: AREA-01 | C35: CAR PARKING AREA | E35: 1 | F35: =J35/(1000*1000) -> 299.76443 | I35: =PRODUCT(E35:H35) -> 299.76443 | J35: 2.9976443e+08
C36: RA BILL-03
C37: RA BILL-04
B38: AREA-01 | C38: MAIN DRIVEWAY 1 SIDE | E38: 1 | F38: 160 | G38: 4.7 | I38: =PRODUCT(E38:H38) -> 752
B39: AREA-02 | C39: ROUNDABOUT AREA | E39: 1 | F39: =J39/1000000 -> 335.14688 | I39: =PRODUCT(E39:H39) -> 335.14688 | J39: 3.3514688e+08
C40: DEDUCTION OF COBBLE AREA | E40: -1 | F40: =J40/1000000 -> 8.0101319 | I40: =PRODUCT(E40:H40) -> -8.0101319 | J40: 8010131.9
E41: -1 | F41: =J41/1000000 -> 1.205132 | I41: =PRODUCT(E41:H41) -> -1.205132 | J41: 1205132
E42: -1 | F42: =J42/1000000 -> 0.8638683 | I42: =PRODUCT(E42:H42) -> -0.8638683 | J42: 863868.3
E43: -1 | F43: =J43/1000000 -> 6.9738893 | I43: =PRODUCT(E43:H43) -> -6.9738893 | J43: 6973889.3
E44: -1 | F44: =J44/1000000 -> 0.9008448 | I44: =PRODUCT(E44:H44) -> -0.9008448 | J44: 900844.8
E45: -1 | F45: =J45/1000000 -> 4.4952174 | I45: =PRODUCT(E45:H45) -> -4.4952174 | J45: 4495217.4
E46: -1 | F46: =J46/1000000 -> 3.2799896 | I46: =PRODUCT(E46:H46) -> -3.2799896 | J46: 3279989.6
E47: -1 | F47: =J47/1000000 -> 5.8909573 | I47: =PRODUCT(E47:H47) -> -5.8909573 | J47: 5890957.3
E48: -1 | F48: =J48/1000000 -> 7.5177032 | I48: =PRODUCT(E48:H48) -> -7.5177032 | J48: 7517703.2
E49: -1 | F49: =J49/1000000 -> 4.6961416 | I49: =PRODUCT(E49:H49) -> -4.6961416 | J49: 4696141.6
E50: -1 | F50: =J50/1000000 -> 2.3182744 | I50: =PRODUCT(E50:H50) -> -2.3182744 | J50: 2318274.4
...

Sheet M BOOK
B2: ='Abstract '!A1 -> Project | C2: ='Abstract '!B1 -> : Sattva City
B3: ='Abstract '!A2 -> Vendor | C3: ='Abstract '!B2 -> : Pragathi Landscapers LLP
B4: ='Abstract '!A3 -> WO NO | C4: ='Abstract '!B3 -> : 4300006116
B5: ='Abstract '!A4 -> WO Value | C5: ='Abstract '!B4 -> : Rs. 1,44,70,656.36/-
B6: ='Abstract '!A5 -> Nature of Work | C6: ='Abstract '!B5 -> : Landscape Works
B7: ='Abstract '!A6 -> RA Bill No | C7: ='Abstract '!B6 -> : 05
B8: ='Abstract '!A7 -> Bill Period | C8: ='Abstract '!B7 -> : 07.05.2025 to 04.07.2025 | H8: DATE:23-10-2025
B9: MEASUREMENT BACK UP-RA BILL-05
B10: SL.NO | C10: DESCRIPTION | D10: UNIT | E10: NOS | F10: L | G10: B | H10: D | I10: QTY | J10: REMARKS
B12: ='Abstract '!A29 -> 10 | C12: ='Abstract '!B29 -> Land_Sup/Fix_Granular Sub Base Providing & laying of Granular Sub-base with Coarse Graded material (Table:- 400-2) compacted thickness of 150mm by providing, laying, spreading and compacting , spreading in uniform layers with motor grader on prepared surface, mixing by mix in place method with rotavator at OMC, and compacting with vibratory roller 8-10 tonne to achieve the desired density of 98% including protection of edges of GSB layer, cost of all materials, labour, hire charges of machinery, loading & Unloading, all lead and lift etc., complete. as per the directions of eng-in- charge of work in accordance Technical Specification
C13: RA BILL-01
B14: AREA-01 | C14: DRIVEWAY FROM ROUND ABOUT TOWARD ENTRACE AREA | D14: CUM | E14: 1 | F14: =J14/(1000*1000) -> 1195.8288 | H14: 0.15 | I14: =PRODUCT(E14:H14) -> 179.37432 | J14: 1.1958288e+09
B15: AREA-02 | C15: PARKING AREA-PATHWAY | E15: 1 | F15: =J15/(1000*1000) -> 352.14081 | H15: 0.15 | I15: =PRODUCT(E15:H15) -> 52.821122 | J15: 3.5214081e+08
C16: PLANTING AREA DEDUCTIONS | E16: -1 | F16: =J16/(1000*1000) -> 31.539406 | H16: 0.15 | I16: =PRODUCT(E16:H16) -> -4.7309109 | J16: 31539406
B17: AREA-03 | C17: PARKING AREA | E17: 1 | F17: =J17/(1000*1000) -> 821.29796 | H17: 0.15 | I17: =PRODUCT(E17:H17) -> 123.19469 | J17: 8.2129796e+08
B18: AREA-2A | C18: PARKING AREA-KERB BASE GSB | E18: 1 | F18: =(J18/1000)-(1.5+2.33) -> 278.7148 | G18: 0.4 | H18: 0.15 | I18: =PRODUCT(E18:H18) -> 16.722888 | J18: 282544.8
C19: PARKING AREA-KERB BASE GSB | E19: 1 | F19: =J19/1000 -> 23.7206 | G19: 0.4 | H19: 0.15 | I19: =PRODUCT(E19:H19) -> 1.423236 | J19: 23720.6
B20: AREA-3A | C20: PARKING AREA-KERB BASE GSB | E20: 1 | F20: =J20/1000 -> 169.7952 | G20: 0.4 | H20: 0.15 | I20: =PRODUCT(E20:H20) -> 10.187712 | J20: 169795.2
C21: RA BILL-02
B22: AREA-01 | C22: MARKETING OFFICE DROP OFF | E22: 1 | F22: =J22/(1000*1000) -> 408.50994 | H22: 0.15 | I22: =PRODUCT(E22:H22) -> 61.276491 | J22: 4.0850994e+08
C23: MEDIAN DEDUCTION | E23: -1 | F23: =J23/(1000*1000) -> 42.792993 | H23: 0.15 | I23: =PRODUCT(E23:H23) -> -6.4189489 | J23: 42792993
B24: AREA-02 | C24: DRIVEWAY BESIDE PATHWAY | E24: 1 | F24: =J24/(1000*1000) -> 113.20324 | H24: 0.15 | I24: =PRODUCT(E24:H24) -> 16.980485 | J24: 1.1320324e+08
B25: AREA-03 | C25: PARKING AREA PEDESTRIAN WALKWAY | E25: 1 | F25: =J25/(1000*1000) -> 79.748774 | H25: 0.15 | I25: =PRODUCT(E25:H25) -> 11.962316 | J25: 79748774
B26: AREA-04 | C26: MARKETING OFFICE DROP OFF PATHWAY | E26: 1 | F26: =J26/(1000*1000) -> 124.33505 | H26: 0.15 | I26: =PRODUCT(E26:H26) -> 18.650257 | J26: 1.2433505e+08
C27: MARKETING OFFICE DROP OFF PATHWAY | E27: 1 | F27: =J27/(1000*1000) -> 35.401722 | H27: 0.15 | I27: =PRODUCT(E27:H27) -> 5.3102583 | J27: 35401722
B28: AREA-05 | C28: MARKETING OFFICE DROP OFF GRANITE AREA | E28: 1 | F28: =J28/(1000*1000) -> 99.827298 | H28: 0.15 | I28: =PRODUCT(E28:H28) -> 14.974095 | J28: 99827298
B29: AREA-06 | C29: MARKETING OFFICE WALKWAY | E29: 1 | F29: =J29/(1000*1000) -> 56.032304 | H29: 0.15 | I29: =PRODUCT(E29:H29) -> 8.4048455 | J29: 56032304
B30: AREA-07 | C30: DRIVEWAY AREA | E30: 1 | F30: =J30/(1000*1000) -> 878.69423 | H30: 0.15 | I30: =PRODUCT(E30:H30) -> 131.80413 | J30: 8.7869423e+08
B31: AREA-08 | C31: ROUND ABOUT | E31: 1 | F31: =J31/(1000*1000) -> 480.0996 | H31: 0.15 | I31: =PRODUCT(E31:H31) -> 72.014939 | J31: 4.800996e+08
C32: KERB AREA GSB
C33: 450MM KERB Below
B34: AREA-02 | C34: MARKETING OFFICE AREA ENTRANCE | E34: 1 | F34: =J34/1000 -> 51.8133 | G34: 0.4 | H34: 0.15 | I34: =PRODUCT(E34:H34) -> 3.108798 | J34: 51813.3
E35: 1 | F35: =J35/1000 -> 20.5444 | G35: 0.4 | H35: 0.15 | I35: =PRODUCT(E35:H35) -> 1.232664 | J35: 20544.4
B36: AREA-03 | C36: ROUND ABOUT AREA | E36: 1 | F36: =J36/1000-10 -> 83.3172 | G36: 0.4 | H36: 0.15 | I36: =PRODUCT(E36:H36) -> 4.999032 | J36: 93317.2
B37: AREA-04 | C37: DRIVEWAY BESIDE WALKWAY | E37: 1 | F37: =J37/1000 -> 132.9259 | G37: 0.4 | H37: 0.15 | I37: =PRODUCT(E37:H37) -> 7.975554 | J37: 132925.9 | K37: 118
B38: AREA-05 | C38: DRIVEWAY BETWEEN PLANTER | E38: 1 | F38: =J38/1000 -> 259.6208 | G38: 0.4 | H38: 0.15 | I38: =PRODUCT(E38:H38) -> 15.577248 | J38: 259620.8
B39: AREA-06 | C39: PARKING AREA KERB | E39: 1 | F39: =J39/1000 -> 20.7902 | G39: 0.4 | H39: 0.15 | I39: =PRODUCT(E39:H39) -> 1.247412 | J39: 20790.2
E40: 1 | F40: =J40/1000 -> 56.0082 | G40: 0.4 | H40: 0.15 | I40: =PRODUCT(E40:H40) -> 3.360492 | J40: 56008.2
C41: 300MM KERB
B42: AREA-01 | C42: MARKETING OFFICE AREA WALKWAY | E42: 1 | F42: =J42/1000 -> 51.6025 | G42: 0.4 | H42: 0.15 | I42: =PRODUCT(E42:H42) -> 3.09615 | J42: 51602.5
...

Sheet NT
B2: NON-TENDERED ITEMS
B4: MEASUREMENT BACK UP
B5: SL.NO | C5: DESCRIPTION | D5: UNIT | E5: NOS | F5: L | G5: B | H5: D | I5: QTY | J5: REMARKS
B7: NT-01 | C7: SAUCER DRAIN | D7: RMT
C8: RA BILL-02
B9: AREA-01 | C9: MARKETING OFFICE DROP OFF | E9: 1 | F9: =J9/1000 -> 50.0706 | I9: =PRODUCT(E9:H9) -> 50.0706 | J9: 50070.6
E10: 1 | F10: =J10/1000 -> 18.7304 | I10: =PRODUCT(E10:H10) -> 18.7304 | J10: 18730.4
C11: RA BILL-03
B12: AREA-01 | C12: MAIN DRIVEWAY AREA | E12: 1 | F12: =J12/1000 -> 120.011 | I12: =PRODUCT(E12:H12) -> 120.011 | J12: 120011
C13: RA BILL-04
B14: AREA-01 | C14: MAIN DRIVEWAY AREA | E14: 1 | F14: =J14/1000 -> 40.0109 | I14: =PRODUCT(E14:H14) -> 40.0109 | J14: 40010.9
C16: RA BILL-04
B17: AREA-01 | C17: MAIN DRIVEWAY AREA | E17: 1 | F17: =J17/1000 -> 40.0109 | I17: =PRODUCT(E17:H17) -> 40.0109 | J17: 40010.9
B18: AREA-02 | C18: ROUNDABOUT AREA | E18: 1 | F18: =J18/1000 -> 22.815 | I18: =PRODUCT(E18:H18) -> 22.815 | J18: 22815
B19: AREA-03 | C19: ROUNDABOUT AREA | E19: 1 | F19: =J19/1000 -> 15.8189 | I19: =PRODUCT(E19:H19) -> 15.8189 | J19: 15818.9
C20: S | I20: =SUM(I9:I19) -> 307.4677 | J20: RMT
B22: SL.NO | C22: DESCRIPTION | D22: UNIT | E22: NOS | F22: L | G22: B | H22: D | I22: QTY | J22: REMARKS
B24: NT-02 | C24: 40MM THICK STEEL GREY FLAMED FINISH GRANITE FLOORING | D24: SQM
C25: RA BILL-02
B26: AREA-01 | C26: MARKETING OFFICE DROP OFF | E26: 1 | F26: =J26/(1000*1000) -> 99.91514 | I26: =PRODUCT(E26:H26) -> 99.91514 | J26: 99915140
C27: MODULE OFFICE FRONT SIDE | E27: 1
C28: TOTAL | I28: =SUM(I26) -> 99.91514 | J28: SQM
B30: SL.NO | C30: DESCRIPTION | D30: UNIT | E30: NOS | F30: L | G30: B | H30: D | I30: QTY | J30: REMARKS
B32: NT-03 | C32: LDPE SHEET 600 MICRON BELOW M30 CONCRETE | D32: SQM
C33: RA BILL-02
B34: AREA-01 | C34: CAR PARKING AREA | E34: 1 | F34: =J34/(1000*1000) -> 299.76443 | I34: =PRODUCT(E34:H34) -> 299.76443 | J34: 2.9976443e+08
C35: RA BILL-03
C36: RA BILL-04
B37: AREA-01 | C37: MAIN DRIVEWAY 1 SIDE | E37: 1 | F37: 160 | G37: 4.7 | I37: =PRODUCT(E37:H37) -> 752
B38: AREA-02 | C38: ROUNDABOUT AREA | E38: 1 | F38: =J38/1000000 -> 335.14688 | I38: =PRODUCT(E38:H38) -> 335.14688 | J38: 3.3514688e+08
C39: DEDUCTION OF COBBLE AREA | E39: -1 | F39: =J39/1000000 -> 8.0101319 | I39: =PRODUCT(E39:H39) -> -8.0101319 | J39: 8010131.9
E40: -1 | F40: =J40/1000000 -> 1.205132 | I40: =PRODUCT(E40:H40) -> -1.205132 | J40: 1205132
E41: -1 | F41: =J41/1000000 -> 0.8638683 | I41: =PRODUCT(E41:H41) -> -0.8638683 | J41: 863868.3
E42: -1 | F42: =J42/1000000 -> 6.9738893 | I42: =PRODUCT(E42:H42) -> -6.9738893 | J42: 6973889.3
E43: -1 | F43: =J43/1000000 -> 0.9008448 | I43: =PRODUCT(E43:H43) -> -0.9008448 | J43: 900844.8
E44: -1 | F44: =J44/1000000 -> 4.4952174 | I44: =PRODUCT(E44:H44) -> -4.4952174 | J44: 4495217.4
E45: -1 | F45: =J45/1000000 -> 3.2799896 | I45: =PRODUCT(E45:H45) -> -3.2799896 | J45: 3279989.6
E46: -1 | F46: =J46/1000000 -> 5.8909573 | I46: =PRODUCT(E46:H46) -> -5.8909573 | J46: 5890957.3
E47: -1 | F47: =J47/1000000 -> 7.5177032 | I47: =PRODUCT(E47:H47) -> -7.5177032 | J47: 7517703.2
E48: -1 | F48: =J48/1000000 -> 4.6961416 | I48: =PRODUCT(E48:H48) -> -4.6961416 | J48: 4696141.6
...

Sheet DCS
C3: DCS AND ISSUE DETAILS
C5: SL NO | D5: DCNOS | E5: DATE | F5: DESCRIPTION | G5: UNIT | H5: QTY | I5: REMARKS
C6: 1 | D6: 657 | E6: 45651 | F6: GSB | G6: 34980 | H6: KG
C7: 2 | D7: 658 | E7: 45651 | F7: GSB | G7: 33800 | H7: KG
C8: 3 | D8: 659 | E8: 45651 | F8: GSB | G8: 34450 | H8: KG
C9: 4 | D9: 660 | E9: 45652 | F9: GSB | G9: 34370 | H9: KG
C10: 5 | D10: 661 | E10: 45652 | F10: GSB | G10: 33950 | H10: KG
C11: 6 | D11: 665 | E11: 45664 | F11: GSB | G11: 33960 | H11: KG
C12: 7 | D12: 666 | E12: 45664 | F12: GSB | G12: 34460 | H12: KG
C13: 8 | D13: 667 | E13: 45665 | F13: GSB | G13: 33450 | H13: KG
C14: 9 | D14: 698 | E14: 45686 | F14: GSB | G14: 38220 | H14: KG
C15: 10 | D15: 685 | E15: 45684 | F15: GSB | G15: 35220 | H15: KG
C16: 11 | D16: 687 | E16: 45685 | F16: GSB | G16: 35150 | H16: KG
C17: 12 | D17: 688 | E17: 45685 | F17: GSB | G17: 34530 | H17: KG
... C32: 27 | D32: 552 | E32: 45694 | F32: GSB | G32: 35910 | H32: KG
E33: RA BILL-02
C34: 28 | D34: 563 | E34: 45701 | F34: GSB | G34: 35890 | H34: KG
C35: 29 | D35: 571 | E35: 45703 | F35: GSB | G35: 36110 | H35: KG
C36: 30 | D36: 591 | E36: 45714 | F36: GSB | G36: 36800 | H36: KG
C37: 31 | D37: 592 | E37: 45714 | F37: GSB | G37: 36800 | H37: KG
C38: 32 | D38: 593 | E38: 45715 | F38: GSB | G38: 36800 | H38: KG
C39: 33 | D39: 600 | E39: 45717 | F39: GSB | G39: 36800 | H39: KG
C40: 34 | D40: 202 | E40: 45720 | F40: GSB | G40: 36800 | H40: KG
C41: 35 | D41: 205 | E41: 45720 | F41: GSB | G41: 36300 | H41: KG
C42: 36 | D42: 206 | E42: 45720 | F42: GSB | G42: 35610 | H42: KG
C43: 37 | D43: 207 | E43: 45726 | F43: GSB | G43: 36800 | H43: KG
C44: 38 | D44: 208 | E44: 45726 | F44: GSB | G44: 36650 | H44: KG
C45: 39 | D45: 209 | E45: 45726 | F45: GSB | G45: 36250 | H45: KG
... C67: 61 | D67: 710 | E67: 45812 | F67: GSB | G67: 37100 | H67: KG
G68: =SUM(G6:G67) -> 2273209
G69: =+G68/2100 -> 1082.4805 | H69: CUM
C70: 1 | D70: 672 | E70: 45678 | F70: WET MIX | G70: 32900 | H70: KG
C71: 2 | D71: 673 | E71: 45679 | F71: WET MIX | G71: 34250 | H71: KG
C72: 3 | D72: 674 | E72: 45679 | F72: WET MIX | G72: 35630 | H72: KG
C73: 4 | D73: 675 | E73: 45679 | F73: WET MIX | G73: 36490 | H73: KG
C74: 5 | D74: 676 | E74: 45680 | F74: WET MIX | G74: 36110 | H74: KG
C75: 6 | D75: 677 | E75: 45680 | F75: WET MIX | G75: 35910 | H75: KG
C76: 7 | D76: 678 | E76: 45680 | F76: WET MIX | G76: 35900 | H76: KG
C77: 8 | D77: 679 | E77: 45680 | F77: WET MIX | G77: 36500 | H77: KG
C78: 9 | D78: 680 | E78: 45680 | F78: WET MIX | G78: 36890 | H78: KG
...

Sheet ISSUE BACKUP
C3: DCS AND ISSUE DETAILS
C5: SL NO | D5: DC/ ISSUE SLIPS | E5: DATE | F5: DESCRIPTION | G5: UNIT | H5: QTY | J5: REMARKS
F6: KERB STONE
C7: 1 | D7: 069 | E7: 45646 | F7: KERB STONE 600*450*100MM | G7: NOS | H7: 360 | J7: 2830 | K7: FULL BATTER
C8: 2 | D8: 069 | E8: 45646 | F8: KERB STONE 600*450*100MM | G8: NOS | H8: 252 | J8: 2829 | K8: FULL BATTER
C9: 3 | D9: 070 | E9: 45647 | F9: KERB STONE 600*450*100MM | G9: NOS | H9: 52 | J9: 2847 | K9: FULL BATTER
C10: 4 | D10: 070 | E10: 45647 | F10: KERB STONE 600*450*100MM | G10: NOS | H10: 156 | J10: 2845 | K10: FULL BATTER
C11: 5 | D11: 070 | E11: 45647 | F11: KERB STONE 600*450*100MM | G11: NOS | H11: 360 | J11: 2830 | K11: FULL BATTER
C12: 5 | D12: 041 | E12: 45709 | F12: KERB STONE 600*450*100MM | G12: NOS | H12: 67 | I12: =SUM(H7:H12) -> 1247 | J12: 3648 | K12: FULL BATTER
C15: 1 | D15: 004 | E15: 45681 | F15: KERB STONE 600*300*100 MM | G15: NOS | H15: 334 | J15: 3277 | K15: FLUSH
C16: 2 | D16: 078 | E16: 45649 | F16: KERB STONE 600*300*100 MM | G16: NOS | H16: 335 | J16: 2947 | K16: FLUSH
C17: 3 | D17: 021 | E17: 45334 | F17: KERB STONE 600*300*100 MM | G17: NOS | H17: 608 | J17: 3532 | K17: FLUSH
C18: 4 | D18: 021 | E18: 45334 | F18: KERB STONE 600*300*100 MM | G18: NOS | H18: 528 | J18: 3531 | K18: FLUSH
C19: 5 | D19: 028 | E19: 45705 | F19: KERB STONE 600*300*100 MM | G19: NOS | H19: 576 | J19: 3599 | K19: FLUSH
C20: 6 | D20: 028 | E20: 45705 | F20: KERB STONE 600*300*100 MM | G20: NOS | H20: 512 | I20: =SUM(H15:H20) -> 2893 | J20: 3597 | K20: FLUSH
C22: 1 | D22: 100 | E22: 45677 | F22: KERB STONE 600*450*150 MM | G22: NOS | H22: 348 | J22: 3230 | K22: FULL BATTER
C23: 2 | D23: 100 | E23: 45677 | F23: KERB STONE 600*450*150 MM | G23: NOS | H23: 340 | J23: ` | K23: FULL BATTER
C24: 3 | D24: 034 | E24: 45707 | F24: KERB STONE 600*450*150 MM | G24: NOS | H24: 48 | K24: FULL BATTER
C25: 4 | D25: 035 | E25: 45706 | F25: KERB STONE 600*450*150 MM | G25: NOS | H25: 300
C26: 5 | D26: 41 | E26: 45709 | F26: KERB STONE 600*450*150 MM | G26: NOS | H26: 227 | I26: =SUM(H22:H26) -> 1263 | J26: 3648
F29: SAUCER DRAIN
C30: 1 | D30: 100 | E30: 45677 | F30: SAUCER DRAIN 600*300*125 MM | G30: NOS | H30: 405 | J30: 3229
C31: 2 | D31: 100 | E31: 45677 | F31: SAUCER DRAIN 600*300*125 MM | G31: NOS | H31: 275 | J31: 3228
C32: 3 | D32: 078 | E32: 45654 | F32: SAUCER DRAIN 600*300*125 MM | G32: NOS | H32: 259 | J32: 2948
C33: 4 | D33: 034 | E33: 45707 | F33: SAUCER DRAIN 600*300*125 MM | G33: NOS | H33: 320
C34: 5 | D34: 034 | E34: 45707 | F34: SAUCER DRAIN 600*300*150 MM | G34: NOS | H34: 75
C35: 6 | D35: 035 | E35: 45706 | F35: SAUCER DRAIN 600*300*150 MM | G35: NOS | H35: 216 | J35: 3611
C36: 7 | D36: 035 | E36: 45706 | F36: SAUCER DRAIN 600*300*150 MM | G36: NOS | H36: 180 | J36: 3612
C37: 8 | D37: 072 | E37: 45649 | F37: SAUCER DRAIN 600*300*125 MM | G37: NOS | H37: 441 | J37: 2874
C38: 9 | D38: 041 | E38: 45709 | F38: SAUCER DRAIN 600*300*125 MM | G38: NOS | H38: 42 | J38: 3648
C39: 10 | D39: 028 | E39: 45705 | F39: SAUCER DRAIN 600*300*150 MM | G39: NOS | H39: 216
C40: 11 | D40: 064 | E40: 45729 | F40: SAUCER DRAIN 600*300*150 MM | G40: NOS | H40: 189
C41: 12 | D41: 064 | E41: 45729 | F41: SAUCER DRAIN 600*300*150 MM | G41: NOS | H41: 172 | I41: =SUM(H30:H41) -> 2790 | J41: 3598
F43: CONCRETE PAVERS
C44: 1 | D44: 070 | E44: 45647 | F44: CONCRETE PAVERS LIGHT GREY-100*200*60MM | G44: SQFT | H44: 1419 | J44: 2847
C45: 2 | D45: 078 | E45: 45654 | F45: CONCRETE PAVERS LIGHT GREY-100*200*60MM | G45: SQFT | H45: 475 | J45: 2947
C46: 3 | D46: 042 | E46: 45709 | F46: CONCRETE PAVERS LIGHT GREY-100*200*60MM | G46: SQFT | H46: 1677 | J46: 3649
C47: 4 | D47: 034 | E47: 45707 | F47: CONCRETE PAVERS LIGHT GREY-100*200*60MM | G47: SQFT | H47: 1806 | J47: 3623
C48: 5 | D48: 040 | E48: 45790 | F48: CONCRETE PAVERS LIGHT GREY-100*200*60MM | G48: SQFT | H48: 1817
C49: 6 | D49: 040 | E49: 45790 | F49: CONCRETE PAVERS LIGHT GREY-100*200*60MM | G49: SQFT | H49: 1817
...
